<?xml version='1.0'?>
<sdf version='1.4'>
  <model name="d_diff_drive_robot">
<!-- No Physics -->
<!--    <static>true</static>
-->

<!-- Physics -->
    <static>false</static>
<!-- Box/Chasis -->
     <link name='chassis'>
        <pose>0 0 .1 0 0 0</pose>

        <collision name='collision'>
          <geometry>
            <box>
              <size>.4 .2 .1</size>
            </box>
          </geometry>
        </collision>

        <visual name='visual'>
          <geometry>
            <box>
              <size>.4 .2 .1</size>
            </box>
          </geometry>
        </visual>

<!-- Caster -->
      <collision name='caster_collision'>
        <pose>-0.15 0 -0.05 0 0 0</pose>
        <geometry>
          <sphere>
          <radius>.05</radius>
        </sphere>
      </geometry>

      <surface>
        <friction>
          <ode>
            <mu>0</mu>
            <mu2>0</mu2>
            <slip1>1.0</slip1>
            <slip2>1.0</slip2>
          </ode>
        </friction>
      </surface>
    </collision>

    <visual name='caster_visual'>
      <pose>-0.15 0 -0.05 0 0 0</pose>
      <geometry>
        <sphere>
          <radius>.05</radius>
        </sphere>
      </geometry>
    </visual>


  </link>


<!-- Left Wheel -->

  <link name="left_wheel">
    <pose>0.1 0.13 0.1 0 1.5707 1.5707</pose>
    <collision name="collision">
      <geometry>
        <cylinder>
          <radius>.1</radius>
          <length>.05</length>
        </cylinder>
      </geometry>
    </collision>
    <visual name="visual">
      <geometry>
        <cylinder>
          <radius>.1</radius>
          <length>.05</length>
        </cylinder>
      </geometry>
    </visual>
  </link>


<!-- Right Wheel -->
  <link name="right_wheel">
    <pose>0.1 -0.13 0.1 0 1.5707 1.5707</pose>
    <collision name="collision">
      <geometry>
        <cylinder>
          <radius>.1</radius>
          <length>.05</length>
        </cylinder>
      </geometry>
    </collision>
    <visual name="visual">
      <geometry>
        <cylinder>
          <radius>.1</radius>
          <length>.05</length>
        </cylinder>
      </geometry>
    </visual>
  </link>

<!-- Axel -->
<joint type="revolute" name="left_wheel_hinge">
    <pose>0 0 -0.03 0 0 0</pose>
    <child>left_wheel</child>
    <parent>chassis</parent>
    <axis>
      <xyz>0 1 0</xyz>
    </axis>
  </joint>

  <joint type="revolute" name="right_wheel_hinge">
    <pose>0 0 0.03 0 0 0</pose>
    <child>right_wheel</child>
    <parent>chassis</parent>
    <axis>
      <xyz>0 1 0</xyz>
    </axis>
  </joint>



<!-- Lidar -->
<!--
<include>
  <uri>model://hokuyo</uri>
  <pose>0.2 0 0.2 0 0 0</pose>
</include>
<joint name="hokuyo_joint" type="revolute">
  <child>hokuyo::link</child>
  <parent>chassis</parent>
  <axis>
    <xyz>0 0 1</xyz>
    <limit>
      <upper>0</upper>
      <lower>0</lower>
    </limit>
  </axis>
</joint>
-->





  <!-- Camera -->
<!--
<link name="cam_link">
  <sensor name='cam_sensor1' type='camera' always_on='1' update_rate='10'>
    <origin pose='0 0 0 0 0 1.57'/>
      <camera>
        <horizontal_fov angle='1.57'/>
        <image width='640' height='480' format='R8G8B8'/>
        <clip near='0.5' far='5'/>
      </camera>
    <plugin name='camera_dump' filename='libcamera_dump.so'/>
  </sensor>
</link>
-->

   <include>
      <uri>model://camera</uri>
      <pose>0.0 -0.05 0.2 0 0 0</pose>
      <name>camera</name>
<!--      <plugin name='camera_dump' filename='libcamera_dump.so'/> -->
    </include>
  <joint name="camera_joint_2" type="revolute">
    <child>camera::link</child>
    <parent>chassis</parent>
    <axis>
      <xyz>0 0 1</xyz>
      <limit>
        <upper>0</upper>
        <lower>0</lower>
      </limit>
    </axis>
  </joint>







    <plugin filename="libmodel_diff_drive.so" name="model_diff_drive_plugin">

      <left_wheel_hinge>left_wheel_hinge</left_wheel_hinge>
      <right_wheel_hinge>right_wheel_hinge</right_wheel_hinge>
    </plugin>
  </model>


</sdf>
